---
생성일: 2022-10-16
tags:
  - java
  - 자바의정석
  - 연습문제
  - 예외
last_modified_at: 2022-10-16
title: 자바의 정석 연습문제 8장 - 예외
category: JAVA
---
### [8-1] 예외처리의 정의와 목적

정의 : 발생할 수 있는 예외(에러아님)를 미리 대비해놓는 것

목적 : 이미 일어날 것을 예상한 예외를 무시하고 정삭적인 실행상태를 유지시키기위해 사용

---
### [8-2] 실행도중 예외가 발생하여 화면에 출력된 내용. 옳지않은것은?

> [!important]  
> java.lang.ArithmeticException : / by zero at ExceptionEx18.method2 (ExceptionEx18.java:12) at ExceptionEx18.method1 (ExceptionEx18.java:8) at ExceptionEx18.main (ExceptionEx18.java:4)  

1. 위의 내용으로 예외 발생 시 호출스택에 존재했던 메소드를 알 수 있음
2. 예외가 발생한 위치는 method2 메소드이며 ExceptionEx18.java파일의 12번째 줄이다
3. 발생한 예외는 AirthmeticException이며, 0으로 나누어서 예외가 발생했다
4. <mark class="hltr-red">method2메소드가 method1메소드를 호출했고 그 위치는 ExceptionEx18.java파일의 8번째 줄이다.</mark> → main메소드가 method1을 호출했고 다음에 method2가 호출되었음

```java
public class test {
	
	static void method1(){
		method2();
	}
	static void method2(){
		method3();
	}
	static void method3(){
		System.out.println("hello");
		System.out.println(1/0);
	}
	public static void main(String[] args) {

		method1();
	}
}
```

위의 예시를 실행시키면

```java
Exception in thread "main" java.lang.ArithmeticException: / by zero
	at test.method3(test.java:29)
	at test.method2(test.java:25)
	at test.method1(test.java:22)
	at test.main(test.java:35)
```

라는 메세지가 뜬다.

실제 method3에서 발생했지만 method3를 호출한 method2도 예외가 발생했다고 처리하고 method2를 호출한 method1과 method1을 호출한 main메소드도 호출한 라인에 예외가 발생한것으로 처리하기떄문임.

---
### [8-3] 오버라이딩이 잘못 된 것을 모두 고르시오

```java
void add(int a, int b) throws InvalidNumberException, NotANumberException {}

class NumberException extends Exception{}
class InvalidNumberException extends Exception{}
class NotANumberException extends Exception{}
```

1. void add(int a, int b) throws InvalidNumberException, NotAnumberException {}
2. void add(int a, int b) throws InvalidNumberException {}
3. void add(int a, int b) throws NotAnumberException {}
4. <mark class="hltr-red">void add(int a, int b) throws Exception {}</mark>
5. <mark class="hltr-red">void add(int a, int b) throws NumberException {}</mark>

오버라이딩시 조상보다 더 많은 예외를 선언할 수 없음. 더 높은 조상을 예외선언해도 마찬가지임. Exception은 모든 예외의 최고조상임.

  
---
### [8-4]다음 중 예외를 잘못 처리한 것은?

```java
void method() throws InvalidNumberException, NotANumberException {}
	
class NumberException extends RuntimeException{}
class InvalidNumberException extends NumberException{}
class NotANumberException extends NumberException {}
```

1. try {method();} catch(Exception e){}
2. try {method();} catch(NumberException e) {} catch(Exception e) {}
3. <mark class="hltr-red">try {method();} catch(Exception e) {} catch(NumberException e) {}</mark>
4. try {method();} catch(InvalidNumberException e) {} catch(NotANumberException e) {}
5. try {method();} catch(NumberException e) {}
6. try {method();} catch(RuntimeException e) {}

Exception은 모든 예외의 최고조상이라서 맨 마지막 catch문에 넣어야함. 첫번째 catch문에서 모든 예외를 처리했으니 다음 catch문에서 처리할 예외가 올 수가 없음

  
---
### [8-5] 실행결과를 적으시오

```java
package _2javajungsuktestEx8;

public class ex8_5 {

	static void method(boolean b) {
		try {
			System.out.println(1);
			if(b) throw new ArithmeticException();
			System.out.println(2);
		}catch(RuntimeException r) {
			System.out.println(3);
			return;
		}catch(Exception e) {
			System.out.println(4);
			return;
		}finally {
			System.out.println(5);
		}
		System.out.println(6);
	}
	
	public static void main(String[] args) {
		method(true);
		method(false);
	}

}
```

method(true)호출 →1 출력 → 매개변수 b가 true라서 ArithmeticException발생 → ArithmeticException이 RuntimeExcpetion의 자손이라서 첫번째 catch블럭으로 감 → 3 출력 → 예외가 처리 됐으니 finally블럭으로 감 → 5출력 → method(false) 호출 → 1출력 → 매개변수 b가 false니까 예외가 발생하지 않음 → 2출력 → 5 출력 → 6 출력

최종적으로 1 3 5 1 2 5 6이 출력된다

  
---
### [8-6] 실행결과를 적으시오

```java
class Exercise8_6 {
public static void main(String[] args) {
	try {
		method1();
	} catch(Exception e) {
		System.out.println(5);
	}
}
static void method1() {
	try {
		method2();
		System.out.println(1);
	} catch(ArithmeticException e) {
		System.out.println(2);
	} finally {
		System.out.println(3);
	}
	System.out.println(4);
} // method1()
static void method2() {
	throw new NullPointerException();
}
```

mothod1 → mothod2에서 NullPointerException발생 → 다시 method1으로 돌아가서 발생한 NullPointerException때문에 finally블럭으로 이동 → 3 출력 → method1의 try-catch문 종료 → 발생한 NullPointerException이 해결되지못해서 4가 출력되지못하고 method1 종료 → 다시 method1으로 해결못한 NullPointerException이 main의 try-catch문을 만나(Exception이 최고조상이라 모든 Exception을 처리가능) 5출력

최종적으로 3 5 출력됨

  
---
### [8-7] 실행결과를 적으세요

```java
class Exercise8_7 {
	static void method(boolean b) {
		try {
			System.out.println(1);
			if(b) System.exit(0);
			System.out.println(2);
		} catch(RuntimeException r) {
			System.out.println(3);
			return;
		} catch(Exception e) {
			System.out.println(4);
			return;
		} finally {
			System.out.println(5);
		}
		System.out.println(6);
	}
	public static void main(String[] args) {
		method(true);
		method(false);
	} // main
}
```

main에서 매개변수에 true가 들어간 생태로 method실행 → try-catch문으로 들어가 1 출력 → if(b)가 true니까 프로그램이 종료

최종적으로 1 만 출력되고 종료됨

```java
package Ex8;

import java.util.InputMismatchException;
import java.util.Scanner;

import javax.swing.plaf.synth.SynthSeparatorUI;

public class Ex8_8{
    public static void main(String[] args) {
        //1~100사이의 임의의 값을 얻어서 answer에 저장한다
        int answer = (int)(Math.random()*100)+1;
        int input=0;
        int count=0;

        do{
            Scanner s = new Scanner(System.in);
            try{
                System.out.println("1과 100사이의 값을 입력하세요 : >");
                input = s.nextInt();
            } catch(InputMismatchException e){
                System.out.println("유효하지 않은 값입니다. 다시 값을 입력해주세요.");
                continue;
            }
            count++;
                if(answer>input) System.out.println("더 큰수를 입력하세요.");
            else if(answer <input) System.out.println("더 작은 수를 입력하세요.");
            else {
                System.out.println("맞췄습니다.");
                System.out.println("시도횟수는 "+count+"번 입니다.");
                s.close();
                break;
            }
        }while(true);
    }
}
```

input을 받는 부분을 try-catch문에 넣어서 오류가 발생했을시 에러메세지를 출력하고 다시 try문으로 돌아가도록 continue;를 넣어주었다. catch에 들어갈 Exception은 예제에 적힌

Exception in thread "main" java.util.InputMismatchException  
at java.util.Scanner.throwFor(Scanner.java:819)  
at java.util.Scanner.next(Scanner.java:1431)  
at java.util.Scanner.nextInt(Scanner.java:2040)  
at java.util.Scanner.nextInt(Scanner.java:2000)  
at Exercise8_8.main(Exercise8_8.java:16)  

을 보고 그대로 사용하였다. 그냥 Exception을 써도 될 것같다.

  
---
### [8-9] 다음과 같은 조건의 예외클래스를 작성하시오

![images](/assets/images/java/IMG-20240903140627.png)

```java
package Ex8;

class UnsupportedFunctionException extends RuntimeException {
    final private int ERR_CODE;
    UnsupportedFunctionException(String msg, int errCode){
        super(msg); //조상의 생성자 RuntimeException(String msg)호출
        ERR_CODE=errCode;
    }
    UnsupportedFunctionException(String msg){
        this(msg,100);
    }
    public int getErrorCode(){
        return ERR_CODE;
    }
    public String getMessage(){ //Exception의 getMessage를 오버라이딩
        return "[" + getErrorCode()+"]"+super.getMessage(); 
    }
}

public class Ex8_9 {
    public static void main(String[] args) {
        throw new UnsupportedFunctionException("지원하지 않는 기능입니다.",100);
    }    
}
```

상속이 좀 헷갈리는데 강의를 다시 들어야할거같다
  
---
### [8-10] 실행순서를 적으시오

```java
class Exercise8_10 {
	public static void main(String[] args) {
		try {
			method1();
			System.out.println(6);
		} catch(Exception e) {
			System.out.println(7);
			}
		}
	static void method1() throws Exception {
		try {
			method2();
			System.out.println(1);
		} catch(NullPointerException e) {
			System.out.println(2);
			throw e;
		} catch(Exception e) {
			System.out.println(3);
		} finally {
			System.out.println(4);
		}
			System.out.println(5);
		} // method1()
	static void method2() {
		throw new NullPointerException();
	}
}
```

main → method1 → method2 → NullPointerException발생, method2종료 후 method1으로 돌아감 → method1의 try-catch문의 첫번째 catch문으로 이동, 2출력 + Exception발생. → Exception이 해결하지못한채로 finally로 이동, 4출력 → Exception이 해결되지못해서 5가 출력되지못하고 method1종료 → main의 try-catch문으로 이동 → Exception으로 인해 6이 출력되지못하고 Exception catch문으로 이동 → 7 출력

4 2 7 출력됨